I'm sorry, but an uncaught exception occurred.

While parsing /Users/PoPSiCLe/Dropbox/RenPy-games/HSS/game/config.rpy.
ScriptError: Name (u'/Users/PoPSiCLe/Dropbox/RenPy-games/HSS/game/config.rpy', 1521769244, 1) is defined twice, at game/config.rpy:1 and game/config (MacBook-Pros kopi som er i konflikt 2018-03-26).rpyc:1.

-- Full Traceback ------------------------------------------------------------

Full traceback:
  File "/Applications/renpy-6.99.14.1-sdk/renpy/bootstrap.py", line 306, in bootstrap
    renpy.main.main()
  File "/Applications/renpy-6.99.14.1-sdk/renpy/main.py", line 367, in main
    renpy.game.script.load_script()  # sets renpy.game.script.
  File "/Applications/renpy-6.99.14.1-sdk/renpy/script.py", line 266, in load_script
    self.load_appropriate_file(".rpyc", ".rpy", dir, fn, initcode)
  File "/Applications/renpy-6.99.14.1-sdk/renpy/script.py", line 757, in load_appropriate_file
    self.finish_load(stmts, initcode, filename=lastfn)
  File "/Applications/renpy-6.99.14.1-sdk/renpy/script.py", line 423, in finish_load
    bad_node.filename, bad_node.linenumber))
ScriptError: Name (u'/Users/PoPSiCLe/Dropbox/RenPy-games/HSS/game/config.rpy', 1521769244, 1) is defined twice, at game/config.rpy:1 and game/config (MacBook-Pros kopi som er i konflikt 2018-03-26).rpyc:1.

Darwin-17.4.0-x86_64-i386-64bit
Ren'Py 6.99.14.1.3218
 
Mon Mar 26 17:57:46 2018
